Workbook

Sheet 01 Control
A1: PAPA PASTA | MENU & SUPPLIER COSTING MODEL
A2: Master control panel. Every yellow cell is an input you own. Everything else is a formula - do not overtype it.
B4: GLOBAL ASSUMPTIONS - edit the yellow cells only
B5: Assumption | C5: Value | D5: Unit | E5: Why it matters / where it is used
B6: VAT rate | C6: 0.15 | D6: % | E6: Converts excl-VAT costing into menu board prices.
B7: Default waste / over-portion allowance | C7: 0.05 | D7: % | E7: Added to every BOM line unless the line overrides it.
B8: Standard DRIED pasta portion | C8: 111 | D8: g | E8: Dried weight into the basket. Set to hold DRY MATTER constant against the old 140 g fresh portion (140 x 70% = 98 g solids; 111 x 88% = 97.7 g), so the plate the customer eats does not change.
B9: Cooked yield multiplier | C9: 2.2 | D9: x dry | E9: Dried pasta absorbs water on the boil. Portion x this = the weight of pasta that actually lands in the bowl. 111 g dried gives about 244 g cooked.
B10: Flour as-received moisture | C10: 0.12 | D10: % | E10: Bulk flour carries ~12% water. Subtracted to get true dry solids - this is what the yield is built on.
B11: Finished DRIED pasta moisture | C11: 0.12 | D11: % | E11: Shelf-stable dried pasta finishes at or below 12%. Solids / (1 - this) = dried pasta output. This is the number that changed when dried replaced fresh-daily.
B12: Pasta process loss (mix to portioned) | C12: 0.05 | D12: % | E12: Dough lost to mixing, extrusion, trim and trays. Applied AFTER the moisture mass balance.
B13: Central Kitchen labour & energy | C13: 6.5 | D13: R / kg | E13: Cost to cook, chill/freeze and pack one kg of sauce. PLACEHOLDER - replace with real CK numbers.
B14: Central Kitchen overhead & distribution | C14: 4 | D14: R / kg | E14: Rent, plant depreciation, QA and cold-chain delivery per kg. PLACEHOLDER.
B15: Central Kitchen margin to franchisee | C15: 0.25 | D15: % | E15: The mark-up the CK earns selling frozen sauce to franchisees.
B16: Store labour allowance | C16: 0.12 | D16: % | E16: Percentage of food cost carried as store labour, for the fully-loaded view.
B17: Target GP% - Core menu | C17: 0.7 | D17: % | E17: Drives the recommended sell price on Tier 1 dishes.
... B31: Price point C | C31: 135 | D31: R incl | E31: High anchor.
B33: HOW THIS WORKBOOK WORKS
B34: Tab | C34: What it does
B35: 03 Suppliers | C35: Your supplier list. Add every business you approach here first, then use the name in the price tabs.
B36: 04 SKU Master | C36: THE ENGINE - and the tab your team types into. One row per ingredient, five supplier price slots side by side. Columns AK-AQ automatically pick the CHEAPEST price, name the supplier who gave it, and divide by yield to get the usable cost. This is the only ingredient price the rest of the model ever reads.
B37: 05 Packaging Master | C37: Identical five-supplier structure for packaging - store, central kitchen and retail.
B38: 06 Pasta Dough BOM | C38: The four Golden Balance formulas the franchisee makes in-store. Baker's % -> 10 kg batch -> cost per 140 g serving.
B39: 07 Sauce BOM (CK) | C39: The nine core sauces the Central Kitchen makes. Batch cost -> cost per kg -> + CK labour, overhead and pouch -> + CK margin = the transfer price the franchisee pays.
B40: 09 Cost Index | C40: Auto-built bridge. Turns each dough and sauce into a single cost-per-gram the menu tabs can look up.
B41: 10 Core Menu BOM | C41: Tier 1 - the nine signature dishes, three salads and the add-ons, line by line.
B42: 11 Seasonal Menu BOM | C42: Tier 2 - all 36 seasonal drops across the 3-year rotation, line by line.
B43: 11 Final Menu | C43: The answer sheet. Every dish, its cost, its GP and its selling price. Read this one.
B44: 17 Quote Log | C44: The paper trail. Every quote you are ever given, dated, with the reference. Slot 6 and beyond live here, and it is where MOQ, lead time and the quote reference are recorded.
B45: 18 Production Capacity | C45: THE EQUIPMENT TAB. The 9-pot cooker, the sauce warmers, the wok cookers, the extruder and the drying racks as variables - covers per hour by station, the binding bottleneck, and whether the store can dry enough pasta overnight to serve what it can sell tomorrow. Also the sauce station loadout: which sauce sits in a warmer and which is finished to order.
... B47: 20 Quote Coverage | C47: READ ME - which SKUs still need supplier quotes; turns green as quotes land on 04/05.
B49: COLOUR LEGEND
B50: Yellow fill, blue text | C50: You type here. An input you own.
B51: White / grey, black text | C51: Formula. Do not overtype - it will break the chain.
B52: Green fill | C52: A final answer the rest of the model reads.
B53: Red text | C53: A flag that needs your decision.
B56: LOCKED - settled decisions. Everything below is closed; do not reopen it in the model.
C57: What is now fixed | E57: Detail
B58: DRIED IN STORE, SERVED FRESH. (Ricardo, 6 Sep 2026 - closes the fresh-vs-dried conflict) | E58: Extrude on the GUSGT108, dry on fan-assisted mesh racks, re-bag into sealed ambient bins, portion DRIED into the basket, boil 90-180 s, finish in the wok. The Kitchen Workflow OPS pack was right about the process; the brand position stays 'fresh' - made in this store, this morning, in front of the customer. Portion is 111 g dried, set to hold DRY MATTER constant against the old 140 g fresh portion (140 x 70% = 98 g solids; 111 x 88% = 97.7 g). That is deliberate: the plate the customer eats, the servings per batch and every Aug-2026 cost benchmark are all unchanged.
B59: Ambient pasta storage. No pasta fridge in store. | E59: Dried pasta goes into sealed bins at room temperature with roughly a 30-day life, not 5-7 chilled days. This is what resolves the OPS pack's missing refrigerated pasta storage - there was never meant to be any. The undercounter fridges stay for sauces, mise en place and toppings.
...

Sheet 02 Lists
A1: LISTS & UNIT CONVERSIONS
A2: The conversion table turns a pack price into a cost per gram, millilitre or unit. Add a row if you buy in a unit that is not listed. The lists on the right feed every dropdown in the workbook.
A4: Pack Unit | B4: Base Units | C4: Meaning | E4: Base Unit | F4: Component Type | G4: VAT Basis | H4: RFQ Status | I4: Team Member
A5: g | B5: 1 | C5: gram | E5: g | F5: Pasta | G5: Excl VAT | H5: Not started | I5: PPP1
A6: kg | B6: 1000 | C6: kilogram | E6: ml | F6: Sauce | G6: Incl VAT | H6: Requested | I6: PPP2
A7: mg | B7: 0.001 | C7: milligram | E7: ea | F7: Protein | H7: Chasing | I7: Ricardo
A8: ml | B8: 1 | C8: millilitre | F8: Ingredient | H8: Quoted
A9: L | B9: 1000 | C9: litre | F9: Finish | H9: Declined
A10: ea | B10: 1 | C10: each / unit | F10: Packaging | H10: On hold
A11: pack | B11: 1 | C11: pack treated as 1 unit
A12: case | B12: 1 | C12: case treated as 1 unit - enter total units in Pack Qty
A13: doz | B13: 12 | C13: dozen | E13: Team Member: two people collect quotes (PPP1, PPP2) and Ricardo is the third. Overtype the placeholders with real names here and every Assigned To dropdown on 15 RFQ Tracker and every Relationship Owner on 03 Suppliers picks up the change. Names already chosen on those tabs keep the old text, so rename before you allocate.
A14: punnet | B14: 1 | C14: punnet as 1 unit
A15: tray | B15: 1 | C15: tray as 1 unit
A16: box | B16: 1 | C16: box as 1 unit
A17: sleeve | B17: 1 | C17: sleeve as 1 unit
A18: roll | B18: 1 | C18: roll as 1 unit

Sheet 03 Suppliers
A1: SUPPLIER REGISTER
A2: Every supplier you approach goes here first. Use the exact Supplier Name in the price tabs so the cheapest-price formula can name them back to you. QUOTES ARE is important: if a supplier quotes you INCLUDING VAT, set it here and the model strips the VAT for you automatically. Getting this wrong makes every cost from that supplier 15% too high.
A4: Supplier Code | B4: Supplier Name | C4: Categories Supplied | D4: Contact Person | E4: Phone | F4: Email | G4: Status | H4: Payment Terms | I4: Lead Time (days) | J4: MOQ | K4: Delivery Days | L4: Halaal Certified | M4: Notes | N4: Quotes Are | O4: Relationship Owner
A5: SUP-001 | B5: Ferreira Fresh | C5: Fresh produce | G5: Quoting | M5: Existing quotes 16-17 Aug 2026 | N5: Excl VAT | Q5: ='02 Lists'!$G$5&"" | R5: ='02 Lists'!$I$5&""
A6: SUP-002 | B6: The Local Farmer | C6: Mushrooms & microgreens | G6: Quoting | M6: TLF - also the Farmhouse powder supply chain | N6: Excl VAT | Q6: ='02 Lists'!$G$6&"" | R6: ='02 Lists'!$I$6&""
A7: SUP-003 | G7: To approach | N7: Excl VAT | R7: ='02 Lists'!$I$7&""
A8: SUP-004 | G8: To approach | N8: Excl VAT
A9: SUP-005 | G9: To approach | N9: Excl VAT
A10: SUP-006 | G10: To approach | N10: Excl VAT
A11: SUP-007 | G11: To approach | N11: Excl VAT
A12: SUP-008 | G12: To approach | N12: Excl VAT
N13: Excl VAT
N14: Excl VAT
N15: Excl VAT
N16: Excl VAT
N17: Excl VAT
N18: Excl VAT
N19: Excl VAT
N20: Excl VAT
N21: Excl VAT
N22: Excl VAT
N23: Excl VAT
N24: Excl VAT
... N34: Excl VAT

Sheet 04 SKU Master
A1: INGREDIENT SKU MASTER - 5 SUPPLIER PRICE SLOTS
A2: Type each supplier's pack price into their slot. Columns AK-AQ pick the cheapest automatically. USABLE Cost per Base Unit (column AM) is the single number every recipe in this workbook reads.
A3: THE ITEM | G3: SUPPLIER 1 | M3: SUPPLIER 2 | S3: SUPPLIER 3 | Y3: SUPPLIER 4 | AE3: SUPPLIER 5 | AK3: LOWEST PRICE - CALCULATED, DO NOT TYPE HERE
A4: Ingredient SKU | B4: Category | C4: Item Description | D4: Base Unit | E4: Yield % | F4: Spec / Notes | G4: Supplier Name | H4: Pack Qty | I4: Pack Unit | J4: Pack Cost (as quoted) | K4: Quote Date | L4: Cost per Base Unit | M4: Supplier Name | N4: Pack Qty | O4: Pack Unit | P4: Pack Cost (as quoted) | Q4: Quote Date | R4: Cost per Base Unit | S4: Supplier Name | T4: Pack Qty | U4: Pack Unit | V4: Pack Cost (as quoted) | W4: Quote Date | X4: Cost per Base Unit | Y4: Supplier Name | Z4: Pack Qty | AA4: Pack Unit | AB4: Pack Cost (as quoted) | AC4: Quote Date | AD4: Cost per Base Unit | AE4: Supplier Name | AF4: Pack Qty | AG4: Pack Unit | AH4: Pack Cost (as quoted) | AI4: Quote Date | AJ4: Cost per Base Unit | AK4: LOWEST Cost per Base Unit | AL4: CHEAPEST Supplier | AM4: USABLE Cost per Base Unit (after yield) | AN4: Quotes Held | AO4: Highest Cost per Base Unit | AP4: Price Spread | AQ4: Best Quote Date
A5: PP-WHEAT-SA | B5: Flour / Dough | C5: SA stone-milled whole wheat flour | D5: g | E5: 1 | F5: Strong bread wheat, protein >=13% | L5: =IF(OR($J5="",$H5="",$H5=0),"",$J5/(1+IF(IFERROR(INDEX('03 Suppliers'!$N$5:$N$34,MATCH($G5,'03 Suppliers'!$B$5:$B$34,0)),"Excl VAT")="Incl VAT",'01 Control'!$C$6,0))/($H5*IFERROR(VLOOKUP($I5,'02 Lists'!$A$5:$B$18,2,FALSE()),1))) | R5: =IF(OR($P5="",$N5="",$N5=0),"",$P5/(1+IF(IFERROR(INDEX('03 Suppliers'!$N$5:$N$34,MATCH($M5,'03 Suppliers'!$B$5:$B$34,0)),"Excl VAT")="Incl VAT",'01 Control'!$C$6,0))/($N5*IFERROR(VLOOKUP($O5,'02 Lists'!$A$5:$B$18,2,FALSE()),1))) | X5: =IF(OR($V5="",$T5="",$T5=0),"",$V5/(1+IF(IFERROR(INDEX('03 Suppliers'!$N$5:$N$34,MATCH($S5,'03 Suppliers'!$B$5:$B$34,0)),"Excl VAT")="Incl VAT",'01 Control'!$C$6,0))/($T5*IFERROR(VLOOKUP($U5,'02 Lists'!$A$5:$B$18,2,FALSE()),1))) | AD5: =IF(OR($AB5="",$Z5="",$Z5=0),"",$AB5/(1+IF(IFERROR(INDEX('03 Suppliers'!$N$5:$N$34,MATCH($Y5,'03 Suppliers'!$B$5:$B$34,0)),"Excl VAT")="Incl VAT",'01 Control'!$C$6,0))/($Z5*IFERROR(VLOOKUP($AA5,'02 Lists'!$A$5:$B$18,2,FALSE()),1))) | AJ5: =IF(OR($AH5="",$AF5="",$AF5=0),"",$AH5/(1+IF(IFERROR(INDEX('03 Suppliers'!$N$5:$N$34,MATCH($AE5,'03 Suppliers'!$B$5:$B$34,0)),"Excl VAT")="Incl VAT",'01 Control'!$C$6,0))/($AF5*IFERROR(VLOOKUP($AG5,'02 Lists'!$A$5:$B$18,2,FALSE()),1))) | AK5: =IF(COUNT(L5,R5,X5,AD5,AJ5)=0,"",MIN(L5,R5,X5,AD5,AJ5)) | AL5: =IF($AK5="","",IF(L5=$AK5,$G5,IF(R5=$AK5,$M5,IF(X5=$AK5,$S5,IF(AD5=$AK5,$Y5,IF(AJ5=$AK5,$AE5,"")))))) | AM5: =IF($AK5="","",$AK5/IF($E5="",1,$E5)) | AN5: =COUNT(L5,R5,X5,AD5,AJ5) | AO5: =IF(COUNT(L5,R5,X5,AD5,AJ5)=0,"",MAX(L5,R5,X5,AD5,AJ5)) | AP5: =IF(OR($AK5="",$AO5="",$AO5=0),"",($AO5-$AK5)/$AO5) | AQ5: =IF($AK5="","",IF(L5=$AK5,$K5,IF(R5=$AK5,$Q5,IF(X5=$AK5,$W5,IF(AD5=$AK5,$AC5,IF(AJ5=$AK5,$AI5,"")))))) | AS5: ='02 Lists'!$A$5&"" | AT5: ='03 Suppliers'!$B$5&""
A6: PP-DURUM-WHOLE | B6: Flour / Dough | C6: Whole durum wheat flour | D6: g | E6: 1 | F6: Stone-milled, protein >=13-14%; Protein+ prefers >=14% | L6: =IF(OR($J6="",$H6="",$H6=0),"",$J6/(1+IF(IFERROR(INDEX('03 Suppliers'!$N$5:$N$34,MATCH($G6,'03 Suppliers'!$B$5:$B$34,0)),"Excl VAT")="Incl VAT",'01 Control'!$C$6,0))/($H6*IFERROR(VLOOKUP($I6,'02 Lists'!$A$5:$B$18,2,FALSE()),1))) | R6: =IF(OR($P6="",$N6="",$N6=0),"",$P6/(1+IF(IFERROR(INDEX('03 Suppliers'!$N$5:$N$34,MATCH($M6,'03 Suppliers'!$B$5:$B$34,0)),"Excl VAT")="Incl VAT",'01 Control'!$C$6,0))/($N6*IFERROR(VLOOKUP($O6,'02 Lists'!$A$5:$B$18,2,FALSE()),1))) | X6: =IF(OR($V6="",$T6="",$T6=0),"",$V6/(1+IF(IFERROR(INDEX('03 Suppliers'!$N$5:$N$34,MATCH($S6,'03 Suppliers'!$B$5:$B$34,0)),"Excl VAT")="Incl VAT",'01 Control'!$C$6,0))/($T6*IFERROR(VLOOKUP($U6,'02 Lists'!$A$5:$B$18,2,FALSE()),1))) | AD6: =IF(OR($AB6="",$Z6="",$Z6=0),"",$AB6/(1+IF(IFERROR(INDEX('03 Suppliers'!$N$5:$N$34,MATCH($Y6,'03 Suppliers'!$B$5:$B$34,0)),"Excl VAT")="Incl VAT",'01 Control'!$C$6,0))/($Z6*IFERROR(VLOOKUP($AA6,'02 Lists'!$A$5:$B$18,2,FALSE()),1))) | AJ6: =IF(OR($AH6="",$AF6="",$AF6=0),"",$AH6/(1+IF(IFERROR(INDEX('03 Suppliers'!$N$5:$N$34,MATCH($AE6,'03 Suppliers'!$B$5:$B$34,0)),"Excl VAT")="Incl VAT",'01 Control'!$C$6,0))/($AF6*IFERROR(VLOOKUP($AG6,'02 Lists'!$A$5:$B$18,2,FALSE()),1))) | AK6: =IF(COUNT(L6,R6,X6,AD6,AJ6)=0,"",MIN(L6,R6,X6,AD6,AJ6)) | AL6: =IF($AK6="","",IF(L6=$AK6,$G6,IF(R6=$AK6,$M6,IF(X6=$AK6,$S6,IF(AD6=$AK6,$Y6,IF(AJ6=$AK6,$AE6,"")))))) | AM6: =IF($AK6="","",$AK6/IF($E6="",1,$E6)) | AN6: =COUNT(L6,R6,X6,AD6,AJ6) | AO6: =IF(COUNT(L6,R6,X6,AD6,AJ6)=0,"",MAX(L6,R6,X6,AD6,AJ6)) | AP6: =IF(OR($AK6="",$AO6="",$AO6=0),"",($AO6-$AK6)/$AO6) | AQ6: =IF($AK6="","",IF(L6=$AK6,$K6,IF(R6=$AK6,$Q6,IF(X6=$AK6,$W6,IF(AD6=$AK6,$AC6,IF(AJ6=$AK6,$AI6,"")))))) | AS6: ='02 Lists'!$A$6&"" | AT6: ='03 Suppliers'!$B$6&""
A7: PP-SORGHUM-WHITE | B7: Flour / Dough | C7: SA white sorghum flour | D7: g | E7: 1 | F7: Dehulled, fine mill <=200 um | L7: =IF(OR($J7="",$H7="",$H7=0),"",$J7/(1+IF(IFERROR(INDEX('03 Suppliers'!$N$5:$N$34,MATCH($G7,'03 Suppliers'!$B$5:$B$34,0)),"Excl VAT")="Incl VAT",'01 Control'!$C$6,0))/($H7*IFERROR(VLOOKUP($I7,'02 Lists'!$A$5:$B$18,2,FALSE()),1))) | R7: =IF(OR($P7="",$N7="",$N7=0),"",$P7/(1+IF(IFERROR(INDEX('03 Suppliers'!$N$5:$N$34,MATCH($M7,'03 Suppliers'!$B$5:$B$34,0)),"Excl VAT")="Incl VAT",'01 Control'!$C$6,0))/($N7*IFERROR(VLOOKUP($O7,'02 Lists'!$A$5:$B$18,2,FALSE()),1))) | X7: =IF(OR($V7="",$T7="",$T7=0),"",$V7/(1+IF(IFERROR(INDEX('03 Suppliers'!$N$5:$N$34,MATCH($S7,'03 Suppliers'!$B$5:$B$34,0)),"Excl VAT")="Incl VAT",'01 Control'!$C$6,0))/($T7*IFERROR(VLOOKUP($U7,'02 Lists'!$A$5:$B$18,2,FALSE()),1))) | AD7: =IF(OR($AB7="",$Z7="",$Z7=0),"",$AB7/(1+IF(IFERROR(INDEX('03 Suppliers'!$N$5:$N$34,MATCH($Y7,'03 Suppliers'!$B$5:$B$34,0)),"Excl VAT")="Incl VAT",'01 Control'!$C$6,0))/($Z7*IFERROR(VLOOKUP($AA7,'02 Lists'!$A$5:$B$18,2,FALSE()),1))) | AJ7: =IF(OR($AH7="",$AF7="",$AF7=0),"",$AH7/(1+IF(IFERROR(INDEX('03 Suppliers'!$N$5:$N$34,MATCH($AE7,'03 Suppliers'!$B$5:$B$34,0)),"Excl VAT")="Incl VAT",'01 Control'!$C$6,0))/($AF7*IFERROR(VLOOKUP($AG7,'02 Lists'!$A$5:$B$18,2,FALSE()),1))) | AK7: =IF(COUNT(L7,R7,X7,AD7,AJ7)=0,"",MIN(L7,R7,X7,AD7,AJ7)) | AL7: =IF($AK7="","",IF(L7=$AK7,$G7,IF(R7=$AK7,$M7,IF(X7=$AK7,$S7,IF(AD7=$AK7,$Y7,IF(AJ7=$AK7,$AE7,"")))))) | AM7: =IF($AK7="","",$AK7/IF($E7="",1,$E7)) | AN7: =COUNT(L7,R7,X7,AD7,AJ7) | AO7: =IF(COUNT(L7,R7,X7,AD7,AJ7)=0,"",MAX(L7,R7,X7,AD7,AJ7)) | AP7: =IF(OR($AK7="",$AO7="",$AO7=0),"",($AO7-$AK7)/$AO7) | AQ7: =IF($AK7="","",IF(L7=$AK7,$K7,IF(R7=$AK7,$Q7,IF(X7=$AK7,$W7,IF(AD7=$AK7,$AC7,IF(AJ7=$AK7,$AI7,"")))))) | AS7: ='02 Lists'!$A$7&"" | AT7: ='03 Suppliers'!$B$7&""
A8: PP-BAOBAB | B8: Flour / Dough | C8: SA baobab fruit powder | D8: g | E8: 1 | F8: Soluble fibre + vitamin C. LARGEST SINGLE COST SWING in 3 of 4 formulas - quote this first | L8: =IF(OR($J8="",$H8="",$H8=0),"",$J8/(1+IF(IFERROR(INDEX('03 Suppliers'!$N$5:$N$34,MATCH($G8,'03 Suppliers'!$B$5:$B$34,0)),"Excl VAT")="Incl VAT",'01 Control'!$C$6,0))/($H8*IFERROR(VLOOKUP($I8,'02 Lists'!$A$5:$B$18,2,FALSE()),1))) | R8: =IF(OR($P8="",$N8="",$N8=0),"",$P8/(1+IF(IFERROR(INDEX('03 Suppliers'!$N$5:$N$34,MATCH($M8,'03 Suppliers'!$B$5:$B$34,0)),"Excl VAT")="Incl VAT",'01 Control'!$C$6,0))/($N8*IFERROR(VLOOKUP($O8,'02 Lists'!$A$5:$B$18,2,FALSE()),1))) | X8: =IF(OR($V8="",$T8="",$T8=0),"",$V8/(1+IF(IFERROR(INDEX('03 Suppliers'!$N$5:$N$34,MATCH($S8,'03 Suppliers'!$B$5:$B$34,0)),"Excl VAT")="Incl VAT",'01 Control'!$C$6,0))/($T8*IFERROR(VLOOKUP($U8,'02 Lists'!$A$5:$B$18,2,FALSE()),1))) | AD8: =IF(OR($AB8="",$Z8="",$Z8=0),"",$AB8/(1+IF(IFERROR(INDEX('03 Suppliers'!$N$5:$N$34,MATCH($Y8,'03 Suppliers'!$B$5:$B$34,0)),"Excl VAT")="Incl VAT",'01 Control'!$C$6,0))/($Z8*IFERROR(VLOOKUP($AA8,'02 Lists'!$A$5:$B$18,2,FALSE()),1))) | AJ8: =IF(OR($AH8="",$AF8="",$AF8=0),"",$AH8/(1+IF(IFERROR(INDEX('03 Suppliers'!$N$5:$N$34,MATCH($AE8,'03 Suppliers'!$B$5:$B$34,0)),"Excl VAT")="Incl VAT",'01 Control'!$C$6,0))/($AF8*IFERROR(VLOOKUP($AG8,'02 Lists'!$A$5:$B$18,2,FALSE()),1))) | AK8: =IF(COUNT(L8,R8,X8,AD8,AJ8)=0,"",MIN(L8,R8,X8,AD8,AJ8)) | AL8: =IF($AK8="","",IF(L8=$AK8,$G8,IF(R8=$AK8,$M8,IF(X8=$AK8,$S8,IF(AD8=$AK8,$Y8,IF(AJ8=$AK8,$AE8,"")))))) | AM8: =IF($AK8="","",$AK8/IF($E8="",1,$E8)) | AN8: =COUNT(L8,R8,X8,AD8,AJ8) | AO8: =IF(COUNT(L8,R8,X8,AD8,AJ8)=0,"",MAX(L8,R8,X8,AD8,AJ8)) | AP8: =IF(OR($AK8="",$AO8="",$AO8=0),"",($AO8-$AK8)/$AO8) | AQ8: =IF($AK8="","",IF(L8=$AK8,$K8,IF(R8=$AK8,$Q8,IF(X8=$AK8,$W8,IF(AD8=$AK8,$AC8,IF(AJ8=$AK8,$AI8,"")))))) | AS8: ='02 Lists'!$A$8&"" | AT8: ='03 Suppliers'!$B$8&""
A9: PP-FLAX-GOLDEN | B9: Flour / Dough | C9: Golden flaxseed, cold-milled | D9: g | E9: 1 | F9: Fresh-milled, refrigerated (oxidation control) | L9: =IF(OR($J9="",$H9="",$H9=0),"",$J9/(1+IF(IFERROR(INDEX('03 Suppliers'!$N$5:$N$34,MATCH($G9,'03 Suppliers'!$B$5:$B$34,0)),"Excl VAT")="Incl VAT",'01 Control'!$C$6,0))/($H9*IFERROR(VLOOKUP($I9,'02 Lists'!$A$5:$B$18,2,FALSE()),1))) | R9: =IF(OR($P9="",$N9="",$N9=0),"",$P9/(1+IF(IFERROR(INDEX('03 Suppliers'!$N$5:$N$34,MATCH($M9,'03 Suppliers'!$B$5:$B$34,0)),"Excl VAT")="Incl VAT",'01 Control'!$C$6,0))/($N9*IFERROR(VLOOKUP($O9,'02 Lists'!$A$5:$B$18,2,FALSE()),1))) | X9: =IF(OR($V9="",$T9="",$T9=0),"",$V9/(1+IF(IFERROR(INDEX('03 Suppliers'!$N$5:$N$34,MATCH($S9,'03 Suppliers'!$B$5:$B$34,0)),"Excl VAT")="Incl VAT",'01 Control'!$C$6,0))/($T9*IFERROR(VLOOKUP($U9,'02 Lists'!$A$5:$B$18,2,FALSE()),1))) | AD9: =IF(OR($AB9="",$Z9="",$Z9=0),"",$AB9/(1+IF(IFERROR(INDEX('03 Suppliers'!$N$5:$N$34,MATCH($Y9,'03 Suppliers'!$B$5:$B$34,0)),"Excl VAT")="Incl VAT",'01 Control'!$C$6,0))/($Z9*IFERROR(VLOOKUP($AA9,'02 Lists'!$A$5:$B$18,2,FALSE()),1))) | AJ9: =IF(OR($AH9="",$AF9="",$AF9=0),"",$AH9/(1+IF(IFERROR(INDEX('03 Suppliers'!$N$5:$N$34,MATCH($AE9,'03 Suppliers'!$B$5:$B$34,0)),"Excl VAT")="Incl VAT",'01 Control'!$C$6,0))/($AF9*IFERROR(VLOOKUP($AG9,'02 Lists'!$A$5:$B$18,2,FALSE()),1))) | AK9: =IF(COUNT(L9,R9,X9,AD9,AJ9)=0,"",MIN(L9,R9,X9,AD9,AJ9)) | AL9: =IF($AK9="","",IF(L9=$AK9,$G9,IF(R9=$AK9,$M9,IF(X9=$AK9,$S9,IF(AD9=$AK9,$Y9,IF(AJ9=$AK9,$AE9,"")))))) | AM9: =IF($AK9="","",$AK9/IF($E9="",1,$E9)) | AN9: =COUNT(L9,R9,X9,AD9,AJ9) | AO9: =IF(COUNT(L9,R9,X9,AD9,AJ9)=0,"",MAX(L9,R9,X9,AD9,AJ9)) | AP9: =IF(OR($AK9="",$AO9="",$AO9=0),"",($AO9-$AK9)/$AO9) | AQ9: =IF($AK9="","",IF(L9=$AK9,$K9,IF(R9=$AK9,$Q9,IF(X9=$AK9,$W9,IF(AD9=$AK9,$AC9,IF(AJ9=$AK9,$AI9,"")))))) | AS9: ='02 Lists'!$A$9&"" | AT9: ='03 Suppliers'!$B$9&""
A10: PP-LUPIN-SWEET | B10: Flour / Dough | C10: SA sweet lupin flour, fermented | D10: g | E10: 1 | F10: LUPIN ALLERGEN - declare CONTAINS LUPIN; dedicated line or full deep-clean. CEILING 20% | L10: =IF(OR($J10="",$H10="",$H10=0),"",$J10/(1+IF(IFERROR(INDEX('03 Suppliers'!$N$5:$N$34,MATCH($G10,'03 Suppliers'!$B$5:$B$34,0)),"Excl VAT")="Incl VAT",'01 Control'!$C$6,0))/($H10*IFERROR(VLOOKUP($I10,'02 Lists'!$A$5:$B$18,2,FALSE()),1))) | R10: =IF(OR($P10="",$N10="",$N10=0),"",$P10/(1+IF(IFERROR(INDEX('03 Suppliers'!$N$5:$N$34,MATCH($M10,'03 Suppliers'!$B$5:$B$34,0)),"Excl VAT")="Incl VAT",'01 Control'!$C$6,0))/($N10*IFERROR(VLOOKUP($O10,'02 Lists'!$A$5:$B$18,2,FALSE()),1))) | X10: =IF(OR($V10="",$T10="",$T10=0),"",$V10/(1+IF(IFERROR(INDEX('03 Suppliers'!$N$5:$N$34,MATCH($S10,'03 Suppliers'!$B$5:$B$34,0)),"Excl VAT")="Incl VAT",'01 Control'!$C$6,0))/($T10*IFERROR(VLOOKUP($U10,'02 Lists'!$A$5:$B$18,2,FALSE()),1))) | AD10: =IF(OR($AB10="",$Z10="",$Z10=0),"",$AB10/(1+IF(IFERROR(INDEX('03 Suppliers'!$N$5:$N$34,MATCH($Y10,'03 Suppliers'!$B$5:$B$34,0)),"Excl VAT")="Incl VAT",'01 Control'!$C$6,0))/($Z10*IFERROR(VLOOKUP($AA10,'02 Lists'!$A$5:$B$18,2,FALSE()),1))) | AJ10: =IF(OR($AH10="",$AF10="",$AF10=0),"",$AH10/(1+IF(IFERROR(INDEX('03 Suppliers'!$N$5:$N$34,MATCH($AE10,'03 Suppliers'!$B$5:$B$34,0)),"Excl VAT")="Incl VAT",'01 Control'!$C$6,0))/($AF10*IFERROR(VLOOKUP($AG10,'02 Lists'!$A$5:$B$18,2,FALSE()),1))) | AK10: =IF(COUNT(L10,R10,X10,AD10,AJ10)=0,"",MIN(L10,R10,X10,AD10,AJ10)) | AL10: =IF($AK10="","",IF(L10=$AK10,$G10,IF(R10=$AK10,$M10,IF(X10=$AK10,$S10,IF(AD10=$AK10,$Y10,IF(AJ10=$AK10,$AE10,"")))))) | AM10: =IF($AK10="","",$AK10/IF($E10="",1,$E10)) | AN10: =COUNT(L10,R10,X10,AD10,AJ10) | AO10: =IF(COUNT(L10,R10,X10,AD10,AJ10)=0,"",MAX(L10,R10,X10,AD10,AJ10)) | AP10: =IF(OR($AK10="",$AO10="",$AO10=0),"",($AO10-$AK10)/$AO10) | AQ10: =IF($AK10="","",IF(L10=$AK10,$K10,IF(R10=$AK10,$Q10,IF(X10=$AK10,$W10,IF(AD10=$AK10,$AC10,IF(AJ10=$AK10,$AI10,"")))))) | AS10: ='02 Lists'!$A$10&"" | AT10: ='03 Suppliers'!$B$10&""
A11: PP-INULIN-HP | B11: Flour / Dough | C11: Inulin HP (DP >=23) | D11: g | E11: 1 | F11: Long-chain, soluble fibre >=90%; 1:1 swap with baobab. CEILING ~12% | L11: =IF(OR($J11="",$H11="",$H11=0),"",$J11/(1+IF(IFERROR(INDEX('03 Suppliers'!$N$5:$N$34,MATCH($G11,'03 Suppliers'!$B$5:$B$34,0)),"Excl VAT")="Incl VAT",'01 Control'!$C$6,0))/($H11*IFERROR(VLOOKUP($I11,'02 Lists'!$A$5:$B$18,2,FALSE()),1))) | R11: =IF(OR($P11="",$N11="",$N11=0),"",$P11/(1+IF(IFERROR(INDEX('03 Suppliers'!$N$5:$N$34,MATCH($M11,'03 Suppliers'!$B$5:$B$34,0)),"Excl VAT")="Incl VAT",'01 Control'!$C$6,0))/($N11*IFERROR(VLOOKUP($O11,'02 Lists'!$A$5:$B$18,2,FALSE()),1))) | X11: =IF(OR($V11="",$T11="",$T11=0),"",$V11/(1+IF(IFERROR(INDEX('03 Suppliers'!$N$5:$N$34,MATCH($S11,'03 Suppliers'!$B$5:$B$34,0)),"Excl VAT")="Incl VAT",'01 Control'!$C$6,0))/($T11*IFERROR(VLOOKUP($U11,'02 Lists'!$A$5:$B$18,2,FALSE()),1))) | AD11: =IF(OR($AB11="",$Z11="",$Z11=0),"",$AB11/(1+IF(IFERROR(INDEX('03 Suppliers'!$N$5:$N$34,MATCH($Y11,'03 Suppliers'!$B$5:$B$34,0)),"Excl VAT")="Incl VAT",'01 Control'!$C$6,0))/($Z11*IFERROR(VLOOKUP($AA11,'02 Lists'!$A$5:$B$18,2,FALSE()),1))) | AJ11: =IF(OR($AH11="",$AF11="",$AF11=0),"",$AH11/(1+IF(IFERROR(INDEX('03 Suppliers'!$N$5:$N$34,MATCH($AE11,'03 Suppliers'!$B$5:$B$34,0)),"Excl VAT")="Incl VAT",'01 Control'!$C$6,0))/($AF11*IFERROR(VLOOKUP($AG11,'02 Lists'!$A$5:$B$18,2,FALSE()),1))) | AK11: =IF(COUNT(L11,R11,X11,AD11,AJ11)=0,"",MIN(L11,R11,X11,AD11,AJ11)) | AL11: =IF($AK11="","",IF(L11=$AK11,$G11,IF(R11=$AK11,$M11,IF(X11=$AK11,$S11,IF(AD11=$AK11,$Y11,IF(AJ11=$AK11,$AE11,"")))))) | AM11: =IF($AK11="","",$AK11/IF($E11="",1,$E11)) | AN11: =COUNT(L11,R11,X11,AD11,AJ11) | AO11: =IF(COUNT(L11,R11,X11,AD11,AJ11)=0,"",MAX(L11,R11,X11,AD11,AJ11)) | AP11: =IF(OR($AK11="",$AO11="",$AO11=0),"",($AO11-$AK11)/$AO11) | AQ11: =IF($AK11="","",IF(L11=$AK11,$K11,IF(R11=$AK11,$Q11,IF(X11=$AK11,$W11,IF(AD11=$AK11,$AC11,IF(AJ11=$AK11,$AI11,"")))))) | AS11: ='02 Lists'!$A$11&"" | AT11: ='03 Suppliers'!$B$11&""
A12: PP-CHICKPEA-KABULI | B12: Flour / Dough | C12: Kabuli chickpea flour, roasted + fermented | D12: g | E12: 1 | F12: Roast/de-hull then ferment. CEILING 25%. Declare voluntarily (not an SA declared allergen) | L12: =IF(OR($J12="",$H12="",$H12=0),"",$J12/(1+IF(IFERROR(INDEX('03 Suppliers'!$N$5:$N$34,MATCH($G12,'03 Suppliers'!$B$5:$B$34,0)),"Excl VAT")="Incl VAT",'01 Control'!$C$6,0))/($H12*IFERROR(VLOOKUP($I12,'02 Lists'!$A$5:$B$18,2,FALSE()),1))) | R12: =IF(OR($P12="",$N12="",$N12=0),"",$P12/(1+IF(IFERROR(INDEX('03 Suppliers'!$N$5:$N$34,MATCH($M12,'03 Suppliers'!$B$5:$B$34,0)),"Excl VAT")="Incl VAT",'01 Control'!$C$6,0))/($N12*IFERROR(VLOOKUP($O12,'02 Lists'!$A$5:$B$18,2,FALSE()),1))) | X12: =IF(OR($V12="",$T12="",$T12=0),"",$V12/(1+IF(IFERROR(INDEX('03 Suppliers'!$N$5:$N$34,MATCH($S12,'03 Suppliers'!$B$5:$B$34,0)),"Excl VAT")="Incl VAT",'01 Control'!$C$6,0))/($T12*IFERROR(VLOOKUP($U12,'02 Lists'!$A$5:$B$18,2,FALSE()),1))) | AD12: =IF(OR($AB12="",$Z12="",$Z12=0),"",$AB12/(1+IF(IFERROR(INDEX('03 Suppliers'!$N$5:$N$34,MATCH($Y12,'03 Suppliers'!$B$5:$B$34,0)),"Excl VAT")="Incl VAT",'01 Control'!$C$6,0))/($Z12*IFERROR(VLOOKUP($AA12,'02 Lists'!$A$5:$B$18,2,FALSE()),1))) | AJ12: =IF(OR($AH12="",$AF12="",$AF12=0),"",$AH12/(1+IF(IFERROR(INDEX('03 Suppliers'!$N$5:$N$34,MATCH($AE12,'03 Suppliers'!$B$5:$B$34,0)),"Excl VAT")="Incl VAT",'01 Control'!$C$6,0))/($AF12*IFERROR(VLOOKUP($AG12,'02 Lists'!$A$5:$B$18,2,FALSE()),1))) | AK12: =IF(COUNT(L12,R12,X12,AD12,AJ12)=0,"",MIN(L12,R12,X12,AD12,AJ12)) | AL12: =IF($AK12="","",IF(L12=$AK12,$G12,IF(R12=$AK12,$M12,IF(X12=$AK12,$S12,IF(AD12=$AK12,$Y12,IF(AJ12=$AK12,$AE12,"")))))) | AM12: =IF($AK12="","",$AK12/IF($E12="",1,$E12)) | AN12: =COUNT(L12,R12,X12,AD12,AJ12) | AO12: =IF(COUNT(L12,R12,X12,AD12,AJ12)=0,"",MAX(L12,R12,X12,AD12,AJ12)) | AP12: =IF(OR($AK12="",$AO12="",$AO12=0),"",($AO12-$AK12)/$AO12) | AQ12: =IF($AK12="","",IF(L12=$AK12,$K12,IF(R12=$AK12,$Q12,IF(X12=$AK12,$W12,IF(AD12=$AK12,$AC12,IF(AJ12=$AK12,$AI12,"")))))) | AS12: ='02 Lists'!$A$12&"" | AT12: ='03 Suppliers'!$B$12&""
A13: PP-MUSHROOM-LIGHT | B13: Flour / Dough | C13: Light mushroom powder (umami layer) | D13: g | E13: 1 | F13: Light-coloured; savoury depth | L13: =IF(OR($J13="",$H13="",$H13=0),"",$J13/(1+IF(IFERROR(INDEX('03 Suppliers'!$N$5:$N$34,MATCH($G13,'03 Suppliers'!$B$5:$B$34,0)),"Excl VAT")="Incl VAT",'01 Control'!$C$6,0))/($H13*IFERROR(VLOOKUP($I13,'02 Lists'!$A$5:$B$18,2,FALSE()),1))) | R13: =IF(OR($P13="",$N13="",$N13=0),"",$P13/(1+IF(IFERROR(INDEX('03 Suppliers'!$N$5:$N$34,MATCH($M13,'03 Suppliers'!$B$5:$B$34,0)),"Excl VAT")="Incl VAT",'01 Control'!$C$6,0))/($N13*IFERROR(VLOOKUP($O13,'02 Lists'!$A$5:$B$18,2,FALSE()),1))) | X13: =IF(OR($V13="",$T13="",$T13=0),"",$V13/(1+IF(IFERROR(INDEX('03 Suppliers'!$N$5:$N$34,MATCH($S13,'03 Suppliers'!$B$5:$B$34,0)),"Excl VAT")="Incl VAT",'01 Control'!$C$6,0))/($T13*IFERROR(VLOOKUP($U13,'02 Lists'!$A$5:$B$18,2,FALSE()),1))) | AD13: =IF(OR($AB13="",$Z13="",$Z13=0),"",$AB13/(1+IF(IFERROR(INDEX('03 Suppliers'!$N$5:$N$34,MATCH($Y13,'03 Suppliers'!$B$5:$B$34,0)),"Excl VAT")="Incl VAT",'01 Control'!$C$6,0))/($Z13*IFERROR(VLOOKUP($AA13,'02 Lists'!$A$5:$B$18,2,FALSE()),1))) | AJ13: =IF(OR($AH13="",$AF13="",$AF13=0),"",$AH13/(1+IF(IFERROR(INDEX('03 Suppliers'!$N$5:$N$34,MATCH($AE13,'03 Suppliers'!$B$5:$B$34,0)),"Excl VAT")="Incl VAT",'01 Control'!$C$6,0))/($AF13*IFERROR(VLOOKUP($AG13,'02 Lists'!$A$5:$B$18,2,FALSE()),1))) | AK13: =IF(COUNT(L13,R13,X13,AD13,AJ13)=0,"",MIN(L13,R13,X13,AD13,AJ13)) | AL13: =IF($AK13="","",IF(L13=$AK13,$G13,IF(R13=$AK13,$M13,IF(X13=$AK13,$S13,IF(AD13=$AK13,$Y13,IF(AJ13=$AK13,$AE13,"")))))) | AM13: =IF($AK13="","",$AK13/IF($E13="",1,$E13)) | AN13: =COUNT(L13,R13,X13,AD13,AJ13) | AO13: =IF(COUNT(L13,R13,X13,AD13,AJ13)=0,"",MAX(L13,R13,X13,AD13,AJ13)) | AP13: =IF(OR($AK13="",$AO13="",$AO13=0),"",($AO13-$AK13)/$AO13) | AQ13: =IF($AK13="","",IF(L13=$AK13,$K13,IF(R13=$AK13,$Q13,IF(X13=$AK13,$W13,IF(AD13=$AK13,$AC13,IF(AJ13=$AK13,$AI13,"")))))) | AS13: ='02 Lists'!$A$13&"" | AT13: ='03 Suppliers'!$B$13&""
A14: PP-OYSTER-POWDER | B14: Flour / Dough | C14: Oyster mushroom powder (The Local Farmer) | D14: g | E14: 1 | F14: Freeze-dried preferred; fine mill <=200 um | L14: =IF(OR($J14="",$H14="",$H14=0),"",$J14/(1+IF(IFERROR(INDEX('03 Suppliers'!$N$5:$N$34,MATCH($G14,'03 Suppliers'!$B$5:$B$34,0)),"Excl VAT")="Incl VAT",'01 Control'!$C$6,0))/($H14*IFERROR(VLOOKUP($I14,'02 Lists'!$A$5:$B$18,2,FALSE()),1))) | R14: =IF(OR($P14="",$N14="",$N14=0),"",$P14/(1+IF(IFERROR(INDEX('03 Suppliers'!$N$5:$N$34,MATCH($M14,'03 Suppliers'!$B$5:$B$34,0)),"Excl VAT")="Incl VAT",'01 Control'!$C$6,0))/($N14*IFERROR(VLOOKUP($O14,'02 Lists'!$A$5:$B$18,2,FALSE()),1))) | X14: =IF(OR($V14="",$T14="",$T14=0),"",$V14/(1+IF(IFERROR(INDEX('03 Suppliers'!$N$5:$N$34,MATCH($S14,'03 Suppliers'!$B$5:$B$34,0)),"Excl VAT")="Incl VAT",'01 Control'!$C$6,0))/($T14*IFERROR(VLOOKUP($U14,'02 Lists'!$A$5:$B$18,2,FALSE()),1))) | AD14: =IF(OR($AB14="",$Z14="",$Z14=0),"",$AB14/(1+IF(IFERROR(INDEX('03 Suppliers'!$N$5:$N$34,MATCH($Y14,'03 Suppliers'!$B$5:$B$34,0)),"Excl VAT")="Incl VAT",'01 Control'!$C$6,0))/($Z14*IFERROR(VLOOKUP($AA14,'02 Lists'!$A$5:$B$18,2,FALSE()),1))) | AJ14: =IF(OR($AH14="",$AF14="",$AF14=0),"",$AH14/(1+IF(IFERROR(INDEX('03 Suppliers'!$N$5:$N$34,MATCH($AE14,'03 Suppliers'!$B$5:$B$34,0)),"Excl VAT")="Incl VAT",'01 Control'!$C$6,0))/($AF14*IFERROR(VLOOKUP($AG14,'02 Lists'!$A$5:$B$18,2,FALSE()),1))) | AK14: =IF(COUNT(L14,R14,X14,AD14,AJ14)=0,"",MIN(L14,R14,X14,AD14,AJ14)) | AL14: =IF($AK14="","",IF(L14=$AK14,$G14,IF(R14=$AK14,$M14,IF(X14=$AK14,$S14,IF(AD14=$AK14,$Y14,IF(AJ14=$AK14,$AE14,"")))))) | AM14: =IF($AK14="","",$AK14/IF($E14="",1,$E14)) | AN14: =COUNT(L14,R14,X14,AD14,AJ14) | AO14: =IF(COUNT(L14,R14,X14,AD14,AJ14)=0,"",MAX(L14,R14,X14,AD14,AJ14)) | AP14: =IF(OR($AK14="",$AO14="",$AO14=0),"",($AO14-$AK14)/$AO14) | AQ14: =IF($AK14="","",IF(L14=$AK14,$K14,IF(R14=$AK14,$Q14,IF(X14=$AK14,$W14,IF(AD14=$AK14,$AC14,IF(AJ14=$AK14,$AI14,"")))))) | AS14: ='02 Lists'!$A$14&"" | AT14: ='03 Suppliers'!$B$14&""
A15: PP-LIONSMANE-POWDER | B15: Flour / Dough | C15: Lion's mane powder (The Local Farmer) | D15: g | E15: 1 | F15: CEILING 5% - sensory limit | L15: =IF(OR($J15="",$H15="",$H15=0),"",$J15/(1+IF(IFERROR(INDEX('03 Suppliers'!$N$5:$N$34,MATCH($G15,'03 Suppliers'!$B$5:$B$34,0)),"Excl VAT")="Incl VAT",'01 Control'!$C$6,0))/($H15*IFERROR(VLOOKUP($I15,'02 Lists'!$A$5:$B$18,2,FALSE()),1))) | R15: =IF(OR($P15="",$N15="",$N15=0),"",$P15/(1+IF(IFERROR(INDEX('03 Suppliers'!$N$5:$N$34,MATCH($M15,'03 Suppliers'!$B$5:$B$34,0)),"Excl VAT")="Incl VAT",'01 Control'!$C$6,0))/($N15*IFERROR(VLOOKUP($O15,'02 Lists'!$A$5:$B$18,2,FALSE()),1))) | X15: =IF(OR($V15="",$T15="",$T15=0),"",$V15/(1+IF(IFERROR(INDEX('03 Suppliers'!$N$5:$N$34,MATCH($S15,'03 Suppliers'!$B$5:$B$34,0)),"Excl VAT")="Incl VAT",'01 Control'!$C$6,0))/($T15*IFERROR(VLOOKUP($U15,'02 Lists'!$A$5:$B$18,2,FALSE()),1))) | AD15: =IF(OR($AB15="",$Z15="",$Z15=0),"",$AB15/(1+IF(IFERROR(INDEX('03 Suppliers'!$N$5:$N$34,MATCH($Y15,'03 Suppliers'!$B$5:$B$34,0)),"Excl VAT")="Incl VAT",'01 Control'!$C$6,0))/($Z15*IFERROR(VLOOKUP($AA15,'02 Lists'!$A$5:$B$18,2,FALSE()),1))) | AJ15: =IF(OR($AH15="",$AF15="",$AF15=0),"",$AH15/(1+IF(IFERROR(INDEX('03 Suppliers'!$N$5:$N$34,MATCH($AE15,'03 Suppliers'!$B$5:$B$34,0)),"Excl VAT")="Incl VAT",'01 Control'!$C$6,0))/($AF15*IFERROR(VLOOKUP($AG15,'02 Lists'!$A$5:$B$18,2,FALSE()),1))) | AK15: =IF(COUNT(L15,R15,X15,AD15,AJ15)=0,"",MIN(L15,R15,X15,AD15,AJ15)) | AL15: =IF($AK15="","",IF(L15=$AK15,$G15,IF(R15=$AK15,$M15,IF(X15=$AK15,$S15,IF(AD15=$AK15,$Y15,IF(AJ15=$AK15,$AE15,"")))))) | AM15: =IF($AK15="","",$AK15/IF($E15="",1,$E15)) | AN15: =COUNT(L15,R15,X15,AD15,AJ15) | AO15: =IF(COUNT(L15,R15,X15,AD15,AJ15)=0,"",MAX(L15,R15,X15,AD15,AJ15)) | AP15: =IF(OR($AK15="",$AO15="",$AO15=0),"",($AO15-$AK15)/$AO15) | AQ15: =IF($AK15="","",IF(L15=$AK15,$K15,IF(R15=$AK15,$Q15,IF(X15=$AK15,$W15,IF(AD15=$AK15,$AC15,IF(AJ15=$AK15,$AI15,"")))))) | AS15: ='02 Lists'!$A$15&"" | AT15: ='03 Suppliers'!$B$15&""
A16: PP-MICROGREEN-POWDER | B16: Flour / Dough | C16: Microgreen powder (The Local Farmer) | D16: g | E16: 1 | F16: CEILING 3%; freeze-dry preferred for colour | L16: =IF(OR($J16="",$H16="",$H16=0),"",$J16/(1+IF(IFERROR(INDEX('03 Suppliers'!$N$5:$N$34,MATCH($G16,'03 Suppliers'!$B$5:$B$34,0)),"Excl VAT")="Incl VAT",'01 Control'!$C$6,0))/($H16*IFERROR(VLOOKUP($I16,'02 Lists'!$A$5:$B$18,2,FALSE()),1))) | R16: =IF(OR($P16="",$N16="",$N16=0),"",$P16/(1+IF(IFERROR(INDEX('03 Suppliers'!$N$5:$N$34,MATCH($M16,'03 Suppliers'!$B$5:$B$34,0)),"Excl VAT")="Incl VAT",'01 Control'!$C$6,0))/($N16*IFERROR(VLOOKUP($O16,'02 Lists'!$A$5:$B$18,2,FALSE()),1))) | X16: =IF(OR($V16="",$T16="",$T16=0),"",$V16/(1+IF(IFERROR(INDEX('03 Suppliers'!$N$5:$N$34,MATCH($S16,'03 Suppliers'!$B$5:$B$34,0)),"Excl VAT")="Incl VAT",'01 Control'!$C$6,0))/($T16*IFERROR(VLOOKUP($U16,'02 Lists'!$A$5:$B$18,2,FALSE()),1))) | AD16: =IF(OR($AB16="",$Z16="",$Z16=0),"",$AB16/(1+IF(IFERROR(INDEX('03 Suppliers'!$N$5:$N$34,MATCH($Y16,'03 Suppliers'!$B$5:$B$34,0)),"Excl VAT")="Incl VAT",'01 Control'!$C$6,0))/($Z16*IFERROR(VLOOKUP($AA16,'02 Lists'!$A$5:$B$18,2,FALSE()),1))) | AJ16: =IF(OR($AH16="",$AF16="",$AF16=0),"",$AH16/(1+IF(IFERROR(INDEX('03 Suppliers'!$N$5:$N$34,MATCH($AE16,'03 Suppliers'!$B$5:$B$34,0)),"Excl VAT")="Incl VAT",'01 Control'!$C$6,0))/($AF16*IFERROR(VLOOKUP($AG16,'02 Lists'!$A$5:$B$18,2,FALSE()),1))) | AK16: =IF(COUNT(L16,R16,X16,AD16,AJ16)=0,"",MIN(L16,R16,X16,AD16,AJ16)) | AL16: =IF($AK16="","",IF(L16=$AK16,$G16,IF(R16=$AK16,$M16,IF(X16=$AK16,$S16,IF(AD16=$AK16,$Y16,IF(AJ16=$AK16,$AE16,"")))))) | AM16: =IF($AK16="","",$AK16/IF($E16="",1,$E16)) | AN16: =COUNT(L16,R16,X16,AD16,AJ16) | AO16: =IF(COUNT(L16,R16,X16,AD16,AJ16)=0,"",MAX(L16,R16,X16,AD16,AJ16)) | AP16: =IF(OR($AK16="",$AO16="",$AO16=0),"",($AO16-$AK16)/$AO16) | AQ16: =IF($AK16="","",IF(L16=$AK16,$K16,IF(R16=$AK16,$Q16,IF(X16=$AK16,$W16,IF(AD16=$AK16,$AC16,IF(AJ16=$AK16,$AI16,"")))))) | AS16: ='02 Lists'!$A$16&"" | AT16: ='03 Suppliers'!$B$16&""
A17: PP-WATER-PURIFIED | B17: Utilities | C17: Purified water (38-40 C) | D17: ml | E17: 1 | F17: Fresh-daily hydration water | L17: =IF(OR($J17="",$H17="",$H17=0),"",$J17/(1+IF(IFERROR(INDEX('03 Suppliers'!$N$5:$N$34,MATCH($G17,'03 Suppliers'!$B$5:$B$34,0)),"Excl VAT")="Incl VAT",'01 Control'!$C$6,0))/($H17*IFERROR(VLOOKUP($I17,'02 Lists'!$A$5:$B$18,2,FALSE()),1))) | R17: =IF(OR($P17="",$N17="",$N17=0),"",$P17/(1+IF(IFERROR(INDEX('03 Suppliers'!$N$5:$N$34,MATCH($M17,'03 Suppliers'!$B$5:$B$34,0)),"Excl VAT")="Incl VAT",'01 Control'!$C$6,0))/($N17*IFERROR(VLOOKUP($O17,'02 Lists'!$A$5:$B$18,2,FALSE()),1))) | X17: =IF(OR($V17="",$T17="",$T17=0),"",$V17/(1+IF(IFERROR(INDEX('03 Suppliers'!$N$5:$N$34,MATCH($S17,'03 Suppliers'!$B$5:$B$34,0)),"Excl VAT")="Incl VAT",'01 Control'!$C$6,0))/($T17*IFERROR(VLOOKUP($U17,'02 Lists'!$A$5:$B$18,2,FALSE()),1))) | AD17: =IF(OR($AB17="",$Z17="",$Z17=0),"",$AB17/(1+IF(IFERROR(INDEX('03 Suppliers'!$N$5:$N$34,MATCH($Y17,'03 Suppliers'!$B$5:$B$34,0)),"Excl VAT")="Incl VAT",'01 Control'!$C$6,0))/($Z17*IFERROR(VLOOKUP($AA17,'02 Lists'!$A$5:$B$18,2,FALSE()),1))) | AJ17: =IF(OR($AH17="",$AF17="",$AF17=0),"",$AH17/(1+IF(IFERROR(INDEX('03 Suppliers'!$N$5:$N$34,MATCH($AE17,'03 Suppliers'!$B$5:$B$34,0)),"Excl VAT")="Incl VAT",'01 Control'!$C$6,0))/($AF17*IFERROR(VLOOKUP($AG17,'02 Lists'!$A$5:$B$18,2,FALSE()),1))) | AK17: =IF(COUNT(L17,R17,X17,AD17,AJ17)=0,"",MIN(L17,R17,X17,AD17,AJ17)) | AL17: =IF($AK17="","",IF(L17=$AK17,$G17,IF(R17=$AK17,$M17,IF(X17=$AK17,$S17,IF(AD17=$AK17,$Y17,IF(AJ17=$AK17,$AE17,"")))))) | AM17: =IF($AK17="","",$AK17/IF($E17="",1,$E17)) | AN17: =COUNT(L17,R17,X17,AD17,AJ17) | AO17: =IF(COUNT(L17,R17,X17,AD17,AJ17)=0,"",MAX(L17,R17,X17,AD17,AJ17)) | AP17: =IF(OR($AK17="",$AO17="",$AO17=0),"",($AO17-$AK17)/$AO17) | AQ17: =IF($AK17="","",IF(L17=$AK17,$K17,IF(R17=$AK17,$Q17,IF(X17=$AK17,$W17,IF(AD17=$AK17,$AC17,IF(AJ17=$AK17,$AI17,"")))))) | AS17: ='02 Lists'!$A$17&"" | AT17: ='03 Suppliers'!$B$17&""
A18: PP-SALT | B18: Dry Goods | C18: Salt | D18: g | E18: 1 | F18: Optional/recommended at 1-1.5% of dry weight | L18: =IF(OR($J18="",$H18="",$H18=0),"",$J18/(1+IF(IFERROR(INDEX('03 Suppliers'!$N$5:$N$34,MATCH($G18,'03 Suppliers'!$B$5:$B$34,0)),"Excl VAT")="Incl VAT",'01 Control'!$C$6,0))/($H18*IFERROR(VLOOKUP($I18,'02 Lists'!$A$5:$B$18,2,FALSE()),1))) | R18: =IF(OR($P18="",$N18="",$N18=0),"",$P18/(1+IF(IFERROR(INDEX('03 Suppliers'!$N$5:$N$34,MATCH($M18,'03 Suppliers'!$B$5:$B$34,0)),"Excl VAT")="Incl VAT",'01 Control'!$C$6,0))/($N18*IFERROR(VLOOKUP($O18,'02 Lists'!$A$5:$B$18,2,FALSE()),1))) | X18: =IF(OR($V18="",$T18="",$T18=0),"",$V18/(1+IF(IFERROR(INDEX('03 Suppliers'!$N$5:$N$34,MATCH($S18,'03 Suppliers'!$B$5:$B$34,0)),"Excl VAT")="Incl VAT",'01 Control'!$C$6,0))/($T18*IFERROR(VLOOKUP($U18,'02 Lists'!$A$5:$B$18,2,FALSE()),1))) | AD18: =IF(OR($AB18="",$Z18="",$Z18=0),"",$AB18/(1+IF(IFERROR(INDEX('03 Suppliers'!$N$5:$N$34,MATCH($Y18,'03 Suppliers'!$B$5:$B$34,0)),"Excl VAT")="Incl VAT",'01 Control'!$C$6,0))/($Z18*IFERROR(VLOOKUP($AA18,'02 Lists'!$A$5:$B$18,2,FALSE()),1))) | AJ18: =IF(OR($AH18="",$AF18="",$AF18=0),"",$AH18/(1+IF(IFERROR(INDEX('03 Suppliers'!$N$5:$N$34,MATCH($AE18,'03 Suppliers'!$B$5:$B$34,0)),"Excl VAT")="Incl VAT",'01 Control'!$C$6,0))/($AF18*IFERROR(VLOOKUP($AG18,'02 Lists'!$A$5:$B$18,2,FALSE()),1))) | AK18: =IF(COUNT(L18,R18,X18,AD18,AJ18)=0,"",MIN(L18,R18,X18,AD18,AJ18)) | AL18: =IF($AK18="","",IF(L18=$AK18,$G18,IF(R18=$AK18,$M18,IF(X18=$AK18,$S18,IF(AD18=$AK18,$Y18,IF(AJ18=$AK18,$AE18,"")))))) | AM18: =IF($AK18="","",$AK18/IF($E18="",1,$E18)) | AN18: =COUNT(L18,R18,X18,AD18,AJ18) | AO18: =IF(COUNT(L18,R18,X18,AD18,AJ18)=0,"",MAX(L18,R18,X18,AD18,AJ18)) | AP18: =IF(OR($AK18="",$AO18="",$AO18=0),"",($AO18-$AK18)/$AO18) | AQ18: =IF($AK18="","",IF(L18=$AK18,$K18,IF(R18=$AK18,$Q18,IF(X18=$AK18,$W18,IF(AD18=$AK18,$AC18,IF(AJ18=$AK18,$AI18,"")))))) | AS18: ='02 Lists'!$A$18&"" | AT18: ='03 Suppliers'!$B$18&""
A19: PP-EVOO | B19: Oil / Fat | C19: Extra-virgin olive oil | D19: ml | E19: 1 | F19: Mouthfeel / aroma carrier; also a finishing item | L19: =IF(OR($J19="",$H19="",$H19=0),"",$J19/(1+IF(IFERROR(INDEX('03 Suppliers'!$N$5:$N$34,MATCH($G19,'03 Suppliers'!$B$5:$B$34,0)),"Excl VAT")="Incl VAT",'01 Control'!$C$6,0))/($H19*IFERROR(VLOOKUP($I19,'02 Lists'!$A$5:$B$18,2,FALSE()),1))) | R19: =IF(OR($P19="",$N19="",$N19=0),"",$P19/(1+IF(IFERROR(INDEX('03 Suppliers'!$N$5:$N$34,MATCH($M19,'03 Suppliers'!$B$5:$B$34,0)),"Excl VAT")="Incl VAT",'01 Control'!$C$6,0))/($N19*IFERROR(VLOOKUP($O19,'02 Lists'!$A$5:$B$18,2,FALSE()),1))) | X19: =IF(OR($V19="",$T19="",$T19=0),"",$V19/(1+IF(IFERROR(INDEX('03 Suppliers'!$N$5:$N$34,MATCH($S19,'03 Suppliers'!$B$5:$B$34,0)),"Excl VAT")="Incl VAT",'01 Control'!$C$6,0))/($T19*IFERROR(VLOOKUP($U19,'02 Lists'!$A$5:$B$18,2,FALSE()),1))) | AD19: =IF(OR($AB19="",$Z19="",$Z19=0),"",$AB19/(1+IF(IFERROR(INDEX('03 Suppliers'!$N$5:$N$34,MATCH($Y19,'03 Suppliers'!$B$5:$B$34,0)),"Excl VAT")="Incl VAT",'01 Control'!$C$6,0))/($Z19*IFERROR(VLOOKUP($AA19,'02 Lists'!$A$5:$B$18,2,FALSE()),1))) | AJ19: =IF(OR($AH19="",$AF19="",$AF19=0),"",$AH19/(1+IF(IFERROR(INDEX('03 Suppliers'!$N$5:$N$34,MATCH($AE19,'03 Suppliers'!$B$5:$B$34,0)),"Excl VAT")="Incl VAT",'01 Control'!$C$6,0))/($AF19*IFERROR(VLOOKUP($AG19,'02 Lists'!$A$5:$B$18,2,FALSE()),1))) | AK19: =IF(COUNT(L19,R19,X19,AD19,AJ19)=0,"",MIN(L19,R19,X19,AD19,AJ19)) | AL19: =IF($AK19="","",IF(L19=$AK19,$G19,IF(R19=$AK19,$M19,IF(X19=$AK19,$S19,IF(AD19=$AK19,$Y19,IF(AJ19=$AK19,$AE19,"")))))) | AM19: =IF($AK19="","",$AK19/IF($E19="",1,$E19)) | AN19: =COUNT(L19,R19,X19,AD19,AJ19) | AO19: =IF(COUNT(L19,R19,X19,AD19,AJ19)=0,"",MAX(L19,R19,X19,AD19,AJ19)) | AP19: =IF(OR($AK19="",$AO19="",$AO19=0),"",($AO19-$AK19)/$AO19) | AQ19: =IF($AK19="","",IF(L19=$AK19,$K19,IF(R19=$AK19,$Q19,IF(X19=$AK19,$W19,IF(AD19=$AK19,$AC19,IF(AJ19=$AK19,$AI19,"")))))) | AS19: ='02 Lists'!$A$19&"" | AT19: ='03 Suppliers'!$B$19&""
A20: PP-OIL | B20: Oil / Fat | C20: Cooking oil (sunflower / canola) | D20: ml | E20: 1 | F20: Commissary soffritto base | L20: =IF(OR($J20="",$H20="",$H20=0),"",$J20/(1+IF(IFERROR(INDEX('03 Suppliers'!$N$5:$N$34,MATCH($G20,'03 Suppliers'!$B$5:$B$34,0)),"Excl VAT")="Incl VAT",'01 Control'!$C$6,0))/($H20*IFERROR(VLOOKUP($I20,'02 Lists'!$A$5:$B$18,2,FALSE()),1))) | R20: =IF(OR($P20="",$N20="",$N20=0),"",$P20/(1+IF(IFERROR(INDEX('03 Suppliers'!$N$5:$N$34,MATCH($M20,'03 Suppliers'!$B$5:$B$34,0)),"Excl VAT")="Incl VAT",'01 Control'!$C$6,0))/($N20*IFERROR(VLOOKUP($O20,'02 Lists'!$A$5:$B$18,2,FALSE()),1))) | X20: =IF(OR($V20="",$T20="",$T20=0),"",$V20/(1+IF(IFERROR(INDEX('03 Suppliers'!$N$5:$N$34,MATCH($S20,'03 Suppliers'!$B$5:$B$34,0)),"Excl VAT")="Incl VAT",'01 Control'!$C$6,0))/($T20*IFERROR(VLOOKUP($U20,'02 Lists'!$A$5:$B$18,2,FALSE()),1))) | AD20: =IF(OR($AB20="",$Z20="",$Z20=0),"",$AB20/(1+IF(IFERROR(INDEX('03 Suppliers'!$N$5:$N$34,MATCH($Y20,'03 Suppliers'!$B$5:$B$34,0)),"Excl VAT")="Incl VAT",'01 Control'!$C$6,0))/($Z20*IFERROR(VLOOKUP($AA20,'02 Lists'!$A$5:$B$18,2,FALSE()),1))) | AJ20: =IF(OR($AH20="",$AF20="",$AF20=0),"",$AH20/(1+IF(IFERROR(INDEX('03 Suppliers'!$N$5:$N$34,MATCH($AE20,'03 Suppliers'!$B$5:$B$34,0)),"Excl VAT")="Incl VAT",'01 Control'!$C$6,0))/($AF20*IFERROR(VLOOKUP($AG20,'02 Lists'!$A$5:$B$18,2,FALSE()),1))) | AK20: =IF(COUNT(L20,R20,X20,AD20,AJ20)=0,"",MIN(L20,R20,X20,AD20,AJ20)) | AL20: =IF($AK20="","",IF(L20=$AK20,$G20,IF(R20=$AK20,$M20,IF(X20=$AK20,$S20,IF(AD20=$AK20,$Y20,IF(AJ20=$AK20,$AE20,"")))))) | AM20: =IF($AK20="","",$AK20/IF($E20="",1,$E20)) | AN20: =COUNT(L20,R20,X20,AD20,AJ20) | AO20: =IF(COUNT(L20,R20,X20,AD20,AJ20)=0,"",MAX(L20,R20,X20,AD20,AJ20)) | AP20: =IF(OR($AK20="",$AO20="",$AO20=0),"",($AO20-$AK20)/$AO20) | AQ20: =IF($AK20="","",IF(L20=$AK20,$K20,IF(R20=$AK20,$Q20,IF(X20=$AK20,$W20,IF(AD20=$AK20,$AC20,IF(AJ20=$AK20,$AI20,"")))))) | AS20: ='02 Lists'!$A$20&"" | AT20: ='03 Suppliers'!$B$20&""
A21: PP-BUTTER | B21: Dairy | C21: Butter, salted | D21: g | E21: 1 | F21: Cream sauce bases | L21: =IF(OR($J21="",$H21="",$H21=0),"",$J21/(1+IF(IFERROR(INDEX('03 Suppliers'!$N$5:$N$34,MATCH($G21,'03 Suppliers'!$B$5:$B$34,0)),"Excl VAT")="Incl VAT",'01 Control'!$C$6,0))/($H21*IFERROR(VLOOKUP($I21,'02 Lists'!$A$5:$B$18,2,FALSE()),1))) | R21: =IF(OR($P21="",$N21="",$N21=0),"",$P21/(1+IF(IFERROR(INDEX('03 Suppliers'!$N$5:$N$34,MATCH($M21,'03 Suppliers'!$B$5:$B$34,0)),"Excl VAT")="Incl VAT",'01 Control'!$C$6,0))/($N21*IFERROR(VLOOKUP($O21,'02 Lists'!$A$5:$B$18,2,FALSE()),1))) | X21: =IF(OR($V21="",$T21="",$T21=0),"",$V21/(1+IF(IFERROR(INDEX('03 Suppliers'!$N$5:$N$34,MATCH($S21,'03 Suppliers'!$B$5:$B$34,0)),"Excl VAT")="Incl VAT",'01 Control'!$C$6,0))/($T21*IFERROR(VLOOKUP($U21,'02 Lists'!$A$5:$B$18,2,FALSE()),1))) | AD21: =IF(OR($AB21="",$Z21="",$Z21=0),"",$AB21/(1+IF(IFERROR(INDEX('03 Suppliers'!$N$5:$N$34,MATCH($Y21,'03 Suppliers'!$B$5:$B$34,0)),"Excl VAT")="Incl VAT",'01 Control'!$C$6,0))/($Z21*IFERROR(VLOOKUP($AA21,'02 Lists'!$A$5:$B$18,2,FALSE()),1))) | AJ21: =IF(OR($AH21="",$AF21="",$AF21=0),"",$AH21/(1+IF(IFERROR(INDEX('03 Suppliers'!$N$5:$N$34,MATCH($AE21,'03 Suppliers'!$B$5:$B$34,0)),"Excl VAT")="Incl VAT",'01 Control'!$C$6,0))/($AF21*IFERROR(VLOOKUP($AG21,'02 Lists'!$A$5:$B$18,2,FALSE()),1))) | AK21: =IF(COUNT(L21,R21,X21,AD21,AJ21)=0,"",MIN(L21,R21,X21,AD21,AJ21)) | AL21: =IF($AK21="","",IF(L21=$AK21,$G21,IF(R21=$AK21,$M21,IF(X21=$AK21,$S21,IF(AD21=$AK21,$Y21,IF(AJ21=$AK21,$AE21,"")))))) | AM21: =IF($AK21="","",$AK21/IF($E21="",1,$E21)) | AN21: =COUNT(L21,R21,X21,AD21,AJ21) | AO21: =IF(COUNT(L21,R21,X21,AD21,AJ21)=0,"",MAX(L21,R21,X21,AD21,AJ21)) | AP21: =IF(OR($AK21="",$AO21="",$AO21=0),"",($AO21-$AK21)/$AO21) | AQ21: =IF($AK21="","",IF(L21=$AK21,$K21,IF(R21=$AK21,$Q21,IF(X21=$AK21,$W21,IF(AD21=$AK21,$AC21,IF(AJ21=$AK21,$AI21,"")))))) | AS21: ='02 Lists'!$A$21&"" | AT21: ='03 Suppliers'!$B$21&""
A22: PP-CHILLI-OIL | B22: Oil / Fat | C22: Chilli oil (finishing, dial-a-heat) | D22: ml | E22: 1 | F22: Store finishing item - Mild/Medium/Hot | L22: =IF(OR($J22="",$H22="",$H22=0),"",$J22/(1+IF(IFERROR(INDEX('03 Suppliers'!$N$5:$N$34,MATCH($G22,'03 Suppliers'!$B$5:$B$34,0)),"Excl VAT")="Incl VAT",'01 Control'!$C$6,0))/($H22*IFERROR(VLOOKUP($I22,'02 Lists'!$A$5:$B$18,2,FALSE()),1))) | R22: =IF(OR($P22="",$N22="",$N22=0),"",$P22/(1+IF(IFERROR(INDEX('03 Suppliers'!$N$5:$N$34,MATCH($M22,'03 Suppliers'!$B$5:$B$34,0)),"Excl VAT")="Incl VAT",'01 Control'!$C$6,0))/($N22*IFERROR(VLOOKUP($O22,'02 Lists'!$A$5:$B$18,2,FALSE()),1))) | X22: =IF(OR($V22="",$T22="",$T22=0),"",$V22/(1+IF(IFERROR(INDEX('03 Suppliers'!$N$5:$N$34,MATCH($S22,'03 Suppliers'!$B$5:$B$34,0)),"Excl VAT")="Incl VAT",'01 Control'!$C$6,0))/($T22*IFERROR(VLOOKUP($U22,'02 Lists'!$A$5:$B$18,2,FALSE()),1))) | AD22: =IF(OR($AB22="",$Z22="",$Z22=0),"",$AB22/(1+IF(IFERROR(INDEX('03 Suppliers'!$N$5:$N$34,MATCH($Y22,'03 Suppliers'!$B$5:$B$34,0)),"Excl VAT")="Incl VAT",'01 Control'!$C$6,0))/($Z22*IFERROR(VLOOKUP($AA22,'02 Lists'!$A$5:$B$18,2,FALSE()),1))) | AJ22: =IF(OR($AH22="",$AF22="",$AF22=0),"",$AH22/(1+IF(IFERROR(INDEX('03 Suppliers'!$N$5:$N$34,MATCH($AE22,'03 Suppliers'!$B$5:$B$34,0)),"Excl VAT")="Incl VAT",'01 Control'!$C$6,0))/($AF22*IFERROR(VLOOKUP($AG22,'02 Lists'!$A$5:$B$18,2,FALSE()),1))) | AK22: =IF(COUNT(L22,R22,X22,AD22,AJ22)=0,"",MIN(L22,R22,X22,AD22,AJ22)) | AL22: =IF($AK22="","",IF(L22=$AK22,$G22,IF(R22=$AK22,$M22,IF(X22=$AK22,$S22,IF(AD22=$AK22,$Y22,IF(AJ22=$AK22,$AE22,"")))))) | AM22: =IF($AK22="","",$AK22/IF($E22="",1,$E22)) | AN22: =COUNT(L22,R22,X22,AD22,AJ22) | AO22: =IF(COUNT(L22,R22,X22,AD22,AJ22)=0,"",MAX(L22,R22,X22,AD22,AJ22)) | AP22: =IF(OR($AK22="",$AO22="",$AO22=0),"",($AO22-$AK22)/$AO22) | AQ22: =IF($AK22="","",IF(L22=$AK22,$K22,IF(R22=$AK22,$Q22,IF(X22=$AK22,$W22,IF(AD22=$AK22,$AC22,IF(AJ22=$AK22,$AI22,"")))))) | AT22: ='03 Suppliers'!$B$22&""
A23: PP-TOM-PLUM | B23: Tomato | C23: San Marzano-style plum tomatoes, tinned | D23: g | E23: 1 | F23: Napoletana / Bolognese / Arrabbiata base | L23: =IF(OR($J23="",$H23="",$H23=0),"",$J23/(1+IF(IFERROR(INDEX('03 Suppliers'!$N$5:$N$34,MATCH($G23,'03 Suppliers'!$B$5:$B$34,0)),"Excl VAT")="Incl VAT",'01 Control'!$C$6,0))/($H23*IFERROR(VLOOKUP($I23,'02 Lists'!$A$5:$B$18,2,FALSE()),1))) | R23: =IF(OR($P23="",$N23="",$N23=0),"",$P23/(1+IF(IFERROR(INDEX('03 Suppliers'!$N$5:$N$34,MATCH($M23,'03 Suppliers'!$B$5:$B$34,0)),"Excl VAT")="Incl VAT",'01 Control'!$C$6,0))/($N23*IFERROR(VLOOKUP($O23,'02 Lists'!$A$5:$B$18,2,FALSE()),1))) | X23: =IF(OR($V23="",$T23="",$T23=0),"",$V23/(1+IF(IFERROR(INDEX('03 Suppliers'!$N$5:$N$34,MATCH($S23,'03 Suppliers'!$B$5:$B$34,0)),"Excl VAT")="Incl VAT",'01 Control'!$C$6,0))/($T23*IFERROR(VLOOKUP($U23,'02 Lists'!$A$5:$B$18,2,FALSE()),1))) | AD23: =IF(OR($AB23="",$Z23="",$Z23=0),"",$AB23/(1+IF(IFERROR(INDEX('03 Suppliers'!$N$5:$N$34,MATCH($Y23,'03 Suppliers'!$B$5:$B$34,0)),"Excl VAT")="Incl VAT",'01 Control'!$C$6,0))/($Z23*IFERROR(VLOOKUP($AA23,'02 Lists'!$A$5:$B$18,2,FALSE()),1))) | AJ23: =IF(OR($AH23="",$AF23="",$AF23=0),"",$AH23/(1+IF(IFERROR(INDEX('03 Suppliers'!$N$5:$N$34,MATCH($AE23,'03 Suppliers'!$B$5:$B$34,0)),"Excl VAT")="Incl VAT",'01 Control'!$C$6,0))/($AF23*IFERROR(VLOOKUP($AG23,'02 Lists'!$A$5:$B$18,2,FALSE()),1))) | AK23: =IF(COUNT(L23,R23,X23,AD23,AJ23)=0,"",MIN(L23,R23,X23,AD23,AJ23)) | AL23: =IF($AK23="","",IF(L23=$AK23,$G23,IF(R23=$AK23,$M23,IF(X23=$AK23,$S23,IF(AD23=$AK23,$Y23,IF(AJ23=$AK23,$AE23,"")))))) | AM23: =IF($AK23="","",$AK23/IF($E23="",1,$E23)) | AN23: =COUNT(L23,R23,X23,AD23,AJ23) | AO23: =IF(COUNT(L23,R23,X23,AD23,AJ23)=0,"",MAX(L23,R23,X23,AD23,AJ23)) | AP23: =IF(OR($AK23="",$AO23="",$AO23=0),"",($AO23-$AK23)/$AO23) | AQ23: =IF($AK23="","",IF(L23=$AK23,$K23,IF(R23=$AK23,$Q23,IF(X23=$AK23,$W23,IF(AD23=$AK23,$AC23,IF(AJ23=$AK23,$AI23,"")))))) | AT23: ='03 Suppliers'!$B$23&""
A24: PP-TOM-PASTE | B24: Tomato | C24: Tomato paste / concentrate | D24: g | E24: 1 | F24: Depth without wine (alcohol-free build) | L24: =IF(OR($J24="",$H24="",$H24=0),"",$J24/(1+IF(IFERROR(INDEX('03 Suppliers'!$N$5:$N$34,MATCH($G24,'03 Suppliers'!$B$5:$B$34,0)),"Excl VAT")="Incl VAT",'01 Control'!$C$6,0))/($H24*IFERROR(VLOOKUP($I24,'02 Lists'!$A$5:$B$18,2,FALSE()),1))) | R24: =IF(OR($P24="",$N24="",$N24=0),"",$P24/(1+IF(IFERROR(INDEX('03 Suppliers'!$N$5:$N$34,MATCH($M24,'03 Suppliers'!$B$5:$B$34,0)),"Excl VAT")="Incl VAT",'01 Control'!$C$6,0))/($N24*IFERROR(VLOOKUP($O24,'02 Lists'!$A$5:$B$18,2,FALSE()),1))) | X24: =IF(OR($V24="",$T24="",$T24=0),"",$V24/(1+IF(IFERROR(INDEX('03 Suppliers'!$N$5:$N$34,MATCH($S24,'03 Suppliers'!$B$5:$B$34,0)),"Excl VAT")="Incl VAT",'01 Control'!$C$6,0))/($T24*IFERROR(VLOOKUP($U24,'02 Lists'!$A$5:$B$18,2,FALSE()),1))) | AD24: =IF(OR($AB24="",$Z24="",$Z24=0),"",$AB24/(1+IF(IFERROR(INDEX('03 Suppliers'!$N$5:$N$34,MATCH($Y24,'03 Suppliers'!$B$5:$B$34,0)),"Excl VAT")="Incl VAT",'01 Control'!$C$6,0))/($Z24*IFERROR(VLOOKUP($AA24,'02 Lists'!$A$5:$B$18,2,FALSE()),1))) | AJ24: =IF(OR($AH24="",$AF24="",$AF24=0),"",$AH24/(1+IF(IFERROR(INDEX('03 Suppliers'!$N$5:$N$34,MATCH($AE24,'03 Suppliers'!$B$5:$B$34,0)),"Excl VAT")="Incl VAT",'01 Control'!$C$6,0))/($AF24*IFERROR(VLOOKUP($AG24,'02 Lists'!$A$5:$B$18,2,FALSE()),1))) | AK24: =IF(COUNT(L24,R24,X24,AD24,AJ24)=0,"",MIN(L24,R24,X24,AD24,AJ24)) | AL24: =IF($AK24="","",IF(L24=$AK24,$G24,IF(R24=$AK24,$M24,IF(X24=$AK24,$S24,IF(AD24=$AK24,$Y24,IF(AJ24=$AK24,$AE24,"")))))) | AM24: =IF($AK24="","",$AK24/IF($E24="",1,$E24)) | AN24: =COUNT(L24,R24,X24,AD24,AJ24) | AO24: =IF(COUNT(L24,R24,X24,AD24,AJ24)=0,"",MAX(L24,R24,X24,AD24,AJ24)) | AP24: =IF(OR($AK24="",$AO24="",$AO24=0),"",($AO24-$AK24)/$AO24) | AQ24: =IF($AK24="","",IF(L24=$AK24,$K24,IF(R24=$AK24,$Q24,IF(X24=$AK24,$W24,IF(AD24=$AK24,$AC24,IF(AJ24=$AK24,$AI24,"")))))) | AT24: ='03 Suppliers'!$B$24&""
A25: PP-SUGAR | B25: Dry Goods | C25: Sugar (acidity balance) | D25: g | E25: 1 | F25: Whisper only - balance, not sweetness | L25: =IF(OR($J25="",$H25="",$H25=0),"",$J25/(1+IF(IFERROR(INDEX('03 Suppliers'!$N$5:$N$34,MATCH($G25,'03 Suppliers'!$B$5:$B$34,0)),"Excl VAT")="Incl VAT",'01 Control'!$C$6,0))/($H25*IFERROR(VLOOKUP($I25,'02 Lists'!$A$5:$B$18,2,FALSE()),1))) | R25: =IF(OR($P25="",$N25="",$N25=0),"",$P25/(1+IF(IFERROR(INDEX('03 Suppliers'!$N$5:$N$34,MATCH($M25,'03 Suppliers'!$B$5:$B$34,0)),"Excl VAT")="Incl VAT",'01 Control'!$C$6,0))/($N25*IFERROR(VLOOKUP($O25,'02 Lists'!$A$5:$B$18,2,FALSE()),1))) | X25: =IF(OR($V25="",$T25="",$T25=0),"",$V25/(1+IF(IFERROR(INDEX('03 Suppliers'!$N$5:$N$34,MATCH($S25,'03 Suppliers'!$B$5:$B$34,0)),"Excl VAT")="Incl VAT",'01 Control'!$C$6,0))/($T25*IFERROR(VLOOKUP($U25,'02 Lists'!$A$5:$B$18,2,FALSE()),1))) | AD25: =IF(OR($AB25="",$Z25="",$Z25=0),"",$AB25/(1+IF(IFERROR(INDEX('03 Suppliers'!$N$5:$N$34,MATCH($Y25,'03 Suppliers'!$B$5:$B$34,0)),"Excl VAT")="Incl VAT",'01 Control'!$C$6,0))/($Z25*IFERROR(VLOOKUP($AA25,'02 Lists'!$A$5:$B$18,2,FALSE()),1))) | AJ25: =IF(OR($AH25="",$AF25="",$AF25=0),"",$AH25/(1+IF(IFERROR(INDEX('03 Suppliers'!$N$5:$N$34,MATCH($AE25,'03 Suppliers'!$B$5:$B$34,0)),"Excl VAT")="Incl VAT",'01 Control'!$C$6,0))/($AF25*IFERROR(VLOOKUP($AG25,'02 Lists'!$A$5:$B$18,2,FALSE()),1))) | AK25: =IF(COUNT(L25,R25,X25,AD25,AJ25)=0,"",MIN(L25,R25,X25,AD25,AJ25)) | AL25: =IF($AK25="","",IF(L25=$AK25,$G25,IF(R25=$AK25,$M25,IF(X25=$AK25,$S25,IF(AD25=$AK25,$Y25,IF(AJ25=$AK25,$AE25,"")))))) | AM25: =IF($AK25="","",$AK25/IF($E25="",1,$E25)) | AN25: =COUNT(L25,R25,X25,AD25,AJ25) | AO25: =IF(COUNT(L25,R25,X25,AD25,AJ25)=0,"",MAX(L25,R25,X25,AD25,AJ25)) | AP25: =IF(OR($AK25="",$AO25="",$AO25=0),"",($AO25-$AK25)/$AO25) | AQ25: =IF($AK25="","",IF(L25=$AK25,$K25,IF(R25=$AK25,$Q25,IF(X25=$AK25,$W25,IF(AD25=$AK25,$AC25,IF(AJ25=$AK25,$AI25,"")))))) | AT25: ='03 Suppliers'!$B$25&""
A26: PP-STOCK-BEEF | B26: Dry Goods | C26: Beef stock / bouillon (halaal) | D26: ml | E26: 1 | F26: Halaal-certified | L26: =IF(OR($J26="",$H26="",$H26=0),"",$J26/(1+IF(IFERROR(INDEX('03 Suppliers'!$N$5:$N$34,MATCH($G26,'03 Suppliers'!$B$5:$B$34,0)),"Excl VAT")="Incl VAT",'01 Control'!$C$6,0))/($H26*IFERROR(VLOOKUP($I26,'02 Lists'!$A$5:$B$18,2,FALSE()),1))) | R26: =IF(OR($P26="",$N26="",$N26=0),"",$P26/(1+IF(IFERROR(INDEX('03 Suppliers'!$N$5:$N$34,MATCH($M26,'03 Suppliers'!$B$5:$B$34,0)),"Excl VAT")="Incl VAT",'01 Control'!$C$6,0))/($N26*IFERROR(VLOOKUP($O26,'02 Lists'!$A$5:$B$18,2,FALSE()),1))) | X26: =IF(OR($V26="",$T26="",$T26=0),"",$V26/(1+IF(IFERROR(INDEX('03 Suppliers'!$N$5:$N$34,MATCH($S26,'03 Suppliers'!$B$5:$B$34,0)),"Excl VAT")="Incl VAT",'01 Control'!$C$6,0))/($T26*IFERROR(VLOOKUP($U26,'02 Lists'!$A$5:$B$18,2,FALSE()),1))) | AD26: =IF(OR($AB26="",$Z26="",$Z26=0),"",$AB26/(1+IF(IFERROR(INDEX('03 Suppliers'!$N$5:$N$34,MATCH($Y26,'03 Suppliers'!$B$5:$B$34,0)),"Excl VAT")="Incl VAT",'01 Control'!$C$6,0))/($Z26*IFERROR(VLOOKUP($AA26,'02 Lists'!$A$5:$B$18,2,FALSE()),1))) | AJ26: =IF(OR($AH26="",$AF26="",$AF26=0),"",$AH26/(1+IF(IFERROR(INDEX('03 Suppliers'!$N$5:$N$34,MATCH($AE26,'03 Suppliers'!$B$5:$B$34,0)),"Excl VAT")="Incl VAT",'01 Control'!$C$6,0))/($AF26*IFERROR(VLOOKUP($AG26,'02 Lists'!$A$5:$B$18,2,FALSE()),1))) | AK26: =IF(COUNT(L26,R26,X26,AD26,AJ26)=0,"",MIN(L26,R26,X26,AD26,AJ26)) | AL26: =IF($AK26="","",IF(L26=$AK26,$G26,IF(R26=$AK26,$M26,IF(X26=$AK26,$S26,IF(AD26=$AK26,$Y26,IF(AJ26=$AK26,$AE26,"")))))) | AM26: =IF($AK26="","",$AK26/IF($E26="",1,$E26)) | AN26: =COUNT(L26,R26,X26,AD26,AJ26) | AO26: =IF(COUNT(L26,R26,X26,AD26,AJ26)=0,"",MAX(L26,R26,X26,AD26,AJ26)) | AP26: =IF(OR($AK26="",$AO26="",$AO26=0),"",($AO26-$AK26)/$AO26) | AQ26: =IF($AK26="","",IF(L26=$AK26,$K26,IF(R26=$AK26,$Q26,IF(X26=$AK26,$W26,IF(AD26=$AK26,$AC26,IF(AJ26=$AK26,$AI26,"")))))) | AT26: ='03 Suppliers'!$B$26&""
A27: PP-STOCK-VEG | B27: Dry Goods | C27: Vegetable stock | D27: ml | E27: 1 | L27: =IF(OR($J27="",$H27="",$H27=0),"",$J27/(1+IF(IFERROR(INDEX('03 Suppliers'!$N$5:$N$34,MATCH($G27,'03 Suppliers'!$B$5:$B$34,0)),"Excl VAT")="Incl VAT",'01 Control'!$C$6,0))/($H27*IFERROR(VLOOKUP($I27,'02 Lists'!$A$5:$B$18,2,FALSE()),1))) | R27: =IF(OR($P27="",$N27="",$N27=0),"",$P27/(1+IF(IFERROR(INDEX('03 Suppliers'!$N$5:$N$34,MATCH($M27,'03 Suppliers'!$B$5:$B$34,0)),"Excl VAT")="Incl VAT",'01 Control'!$C$6,0))/($N27*IFERROR(VLOOKUP($O27,'02 Lists'!$A$5:$B$18,2,FALSE()),1))) | X27: =IF(OR($V27="",$T27="",$T27=0),"",$V27/(1+IF(IFERROR(INDEX('03 Suppliers'!$N$5:$N$34,MATCH($S27,'03 Suppliers'!$B$5:$B$34,0)),"Excl VAT")="Incl VAT",'01 Control'!$C$6,0))/($T27*IFERROR(VLOOKUP($U27,'02 Lists'!$A$5:$B$18,2,FALSE()),1))) | AD27: =IF(OR($AB27="",$Z27="",$Z27=0),"",$AB27/(1+IF(IFERROR(INDEX('03 Suppliers'!$N$5:$N$34,MATCH($Y27,'03 Suppliers'!$B$5:$B$34,0)),"Excl VAT")="Incl VAT",'01 Control'!$C$6,0))/($Z27*IFERROR(VLOOKUP($AA27,'02 Lists'!$A$5:$B$18,2,FALSE()),1))) | AJ27: =IF(OR($AH27="",$AF27="",$AF27=0),"",$AH27/(1+IF(IFERROR(INDEX('03 Suppliers'!$N$5:$N$34,MATCH($AE27,'03 Suppliers'!$B$5:$B$34,0)),"Excl VAT")="Incl VAT",'01 Control'!$C$6,0))/($AF27*IFERROR(VLOOKUP($AG27,'02 Lists'!$A$5:$B$18,2,FALSE()),1))) | AK27: =IF(COUNT(L27,R27,X27,AD27,AJ27)=0,"",MIN(L27,R27,X27,AD27,AJ27)) | AL27: =IF($AK27="","",IF(L27=$AK27,$G27,IF(R27=$AK27,$M27,IF(X27=$AK27,$S27,IF(AD27=$AK27,$Y27,IF(AJ27=$AK27,$AE27,"")))))) | AM27: =IF($AK27="","",$AK27/IF($E27="",1,$E27)) | AN27: =COUNT(L27,R27,X27,AD27,AJ27) | AO27: =IF(COUNT(L27,R27,X27,AD27,AJ27)=0,"",MAX(L27,R27,X27,AD27,AJ27)) | AP27: =IF(OR($AK27="",$AO27="",$AO27=0),"",($AO27-$AK27)/$AO27) | AQ27: =IF($AK27="","",IF(L27=$AK27,$K27,IF(R27=$AK27,$Q27,IF(X27=$AK27,$W27,IF(AD27=$AK27,$AC27,IF(AJ27=$AK27,$AI27,"")))))) | AT27: ='03 Suppliers'!$B$27&""
A28: PP-PEPPER-BLACK | B28: Spice | C28: Black pepper, cracked | D28: g | E28: 1 | F28: Carbonara signature | L28: =IF(OR($J28="",$H28="",$H28=0),"",$J28/(1+IF(IFERROR(INDEX('03 Suppliers'!$N$5:$N$34,MATCH($G28,'03 Suppliers'!$B$5:$B$34,0)),"Excl VAT")="Incl VAT",'01 Control'!$C$6,0))/($H28*IFERROR(VLOOKUP($I28,'02 Lists'!$A$5:$B$18,2,FALSE()),1))) | R28: =IF(OR($P28="",$N28="",$N28=0),"",$P28/(1+IF(IFERROR(INDEX('03 Suppliers'!$N$5:$N$34,MATCH($M28,'03 Suppliers'!$B$5:$B$34,0)),"Excl VAT")="Incl VAT",'01 Control'!$C$6,0))/($N28*IFERROR(VLOOKUP($O28,'02 Lists'!$A$5:$B$18,2,FALSE()),1))) | X28: =IF(OR($V28="",$T28="",$T28=0),"",$V28/(1+IF(IFERROR(INDEX('03 Suppliers'!$N$5:$N$34,MATCH($S28,'03 Suppliers'!$B$5:$B$34,0)),"Excl VAT")="Incl VAT",'01 Control'!$C$6,0))/($T28*IFERROR(VLOOKUP($U28,'02 Lists'!$A$5:$B$18,2,FALSE()),1))) | AD28: =IF(OR($AB28="",$Z28="",$Z28=0),"",$AB28/(1+IF(IFERROR(INDEX('03 Suppliers'!$N$5:$N$34,MATCH($Y28,'03 Suppliers'!$B$5:$B$34,0)),"Excl VAT")="Incl VAT",'01 Control'!$C$6,0))/($Z28*IFERROR(VLOOKUP($AA28,'02 Lists'!$A$5:$B$18,2,FALSE()),1))) | AJ28: =IF(OR($AH28="",$AF28="",$AF28=0),"",$AH28/(1+IF(IFERROR(INDEX('03 Suppliers'!$N$5:$N$34,MATCH($AE28,'03 Suppliers'!$B$5:$B$34,0)),"Excl VAT")="Incl VAT",'01 Control'!$C$6,0))/($AF28*IFERROR(VLOOKUP($AG28,'02 Lists'!$A$5:$B$18,2,FALSE()),1))) | AK28: =IF(COUNT(L28,R28,X28,AD28,AJ28)=0,"",MIN(L28,R28,X28,AD28,AJ28)) | AL28: =IF($AK28="","",IF(L28=$AK28,$G28,IF(R28=$AK28,$M28,IF(X28=$AK28,$S28,IF(AD28=$AK28,$Y28,IF(AJ28=$AK28,$AE28,"")))))) | AM28: =IF($AK28="","",$AK28/IF($E28="",1,$E28)) | AN28: =COUNT(L28,R28,X28,AD28,AJ28) | AO28: =IF(COUNT(L28,R28,X28,AD28,AJ28)=0,"",MAX(L28,R28,X28,AD28,AJ28)) | AP28: =IF(OR($AK28="",$AO28="",$AO28=0),"",($AO28-$AK28)/$AO28) | AQ28: =IF($AK28="","",IF(L28=$AK28,$K28,IF(R28=$AK28,$Q28,IF(X28=$AK28,$W28,IF(AD28=$AK28,$AC28,IF(AJ28=$AK28,$AI28,"")))))) | AT28: ='03 Suppliers'!$B$28&""
A29: PP-CHILLI-FLAKE | B29: Spice | C29: Dried chilli flakes | D29: g | E29: 1 | F29: Arrabbiata / Aglio e Olio | L29: =IF(OR($J29="",$H29="",$H29=0),"",$J29/(1+IF(IFERROR(INDEX('03 Suppliers'!$N$5:$N$34,MATCH($G29,'03 Suppliers'!$B$5:$B$34,0)),"Excl VAT")="Incl VAT",'01 Control'!$C$6,0))/($H29*IFERROR(VLOOKUP($I29,'02 Lists'!$A$5:$B$18,2,FALSE()),1))) | R29: =IF(OR($P29="",$N29="",$N29=0),"",$P29/(1+IF(IFERROR(INDEX('03 Suppliers'!$N$5:$N$34,MATCH($M29,'03 Suppliers'!$B$5:$B$34,0)),"Excl VAT")="Incl VAT",'01 Control'!$C$6,0))/($N29*IFERROR(VLOOKUP($O29,'02 Lists'!$A$5:$B$18,2,FALSE()),1))) | X29: =IF(OR($V29="",$T29="",$T29=0),"",$V29/(1+IF(IFERROR(INDEX('03 Suppliers'!$N$5:$N$34,MATCH($S29,'03 Suppliers'!$B$5:$B$34,0)),"Excl VAT")="Incl VAT",'01 Control'!$C$6,0))/($T29*IFERROR(VLOOKUP($U29,'02 Lists'!$A$5:$B$18,2,FALSE()),1))) | AD29: =IF(OR($AB29="",$Z29="",$Z29=0),"",$AB29/(1+IF(IFERROR(INDEX('03 Suppliers'!$N$5:$N$34,MATCH($Y29,'03 Suppliers'!$B$5:$B$34,0)),"Excl VAT")="Incl VAT",'01 Control'!$C$6,0))/($Z29*IFERROR(VLOOKUP($AA29,'02 Lists'!$A$5:$B$18,2,FALSE()),1))) | AJ29: =IF(OR($AH29="",$AF29="",$AF29=0),"",$AH29/(1+IF(IFERROR(INDEX('03 Suppliers'!$N$5:$N$34,MATCH($AE29,'03 Suppliers'!$B$5:$B$34,0)),"Excl VAT")="Incl VAT",'01 Control'!$C$6,0))/($AF29*IFERROR(VLOOKUP($AG29,'02 Lists'!$A$5:$B$18,2,FALSE()),1))) | AK29: =IF(COUNT(L29,R29,X29,AD29,AJ29)=0,"",MIN(L29,R29,X29,AD29,AJ29)) | AL29: =IF($AK29="","",IF(L29=$AK29,$G29,IF(R29=$AK29,$M29,IF(X29=$AK29,$S29,IF(AD29=$AK29,$Y29,IF(AJ29=$AK29,$AE29,"")))))) | AM29: =IF($AK29="","",$AK29/IF($E29="",1,$E29)) | AN29: =COUNT(L29,R29,X29,AD29,AJ29) | AO29: =IF(COUNT(L29,R29,X29,AD29,AJ29)=0,"",MAX(L29,R29,X29,AD29,AJ29)) | AP29: =IF(OR($AK29="",$AO29="",$AO29=0),"",($AO29-$AK29)/$AO29) | AQ29: =IF($AK29="","",IF(L29=$AK29,$K29,IF(R29=$AK29,$Q29,IF(X29=$AK29,$W29,IF(AD29=$AK29,$AC29,IF(AJ29=$AK29,$AI29,"")))))) | AT29: ='03 Suppliers'!$B$29&""
